<?xml version="1.0"?>
<robot name="myfirst">

  <material name="red">
    <color rgba="1 0 0 1"/>
  </material>
  <material name="white">
    <color rgba="1 1 1 1"/>
  </material>
  <material name="blue">
    <color rgba="0 0 1 1"/>
  </material>

  <link name="base">
    <visual>
      <geometry>
        <box size="0.2 0.2 0.1"/>
      </geometry>
      <origin xyz="0 0 0.05"/>
      <material name="blue"/>
    </visual>
    <collision>
      <geometry>
        <box size="0.2 0.2 0.1"/>
      </geometry>
      <origin xyz="0 0 0.05"/>
    </collision>
  </link>
  <joint name = "base_to_bottom" type="continuous">
    <parent link="base"/>
    <child link="bottom_arm"/>
    <origin xyz="0 0 0.1"/>
    <axis xyz="0 0 1"/>
  </joint>
  <link name="bottom_arm">
    <visual>
      <geometry>
        <box size="0.1 0.1 1"/>
      </geometry>
      <origin xyz="0 0 0.5"/>
      <material name="red"/>
    </visual>
    <collision>
      <geometry>
        <box size="0.1 0.1 1"/>
      </geometry>
      <origin xyz="0 0 0.5"/>
    </collision>
  </link>
  <joint name="bottom_to_middle" type="continuous">
    <parent link="bottom_arm"/>
    <child link="middle_arm"/>
    <origin xyz="0 0 1"/>
    <axis xyz="0 1 0"/>
  </joint>
  <link name="middle_arm">
    <visual>
      <geometry>
        <box size="0.1 0.1 1"/>
      </geometry>
      <origin xyz="0 0 0.5 "/>
      <material name="white"/>
    </visual>
    <collision>
      <geometry>
        <box size="0.1 0.1 1"/>
      </geometry>
      <origin xyz="0 0 0.5 "/>
    </collision>
  </link>
  <joint name="middle_to_top" type="continuous">
    <parent link="middle_arm"/>
    <child link="top_arm"/>
    <origin xyz="0 0 1"/>
    <axis xyz="0 1 0"/>
  </joint>
  <link name="top_arm">
    <visual>
      <geometry>
        <box size="0.1 0.1 1"/>
      </geometry>
      <origin xyz="0 0 0.5"/>
      <material name="blue"/>
    </visual>
    <collision>
      <geometry>
        <box size="0.1 0.1 1"/>
      </geometry>
      <origin xyz="0 0 0.5"/>
    </collision>
  </link>
</robot>
